<?xml version="1.0" ?>
<robot name="RobotC2_0_0">

 <link name="base_link">

 </link>


	<joint name="base_to_capa" type="fixed">
    <parent link="base_link"/>
    <child link="Capa"/>
    <origin rpy="0 0 0" xyz="0.0 0.0 0.0"/>
 	</joint>  

	<joint name="Capa_Chassi2" type="fixed">
    <parent link="Capa"/>
    <child link="Chassi2"/>
    <origin rpy="0  0  0" xyz="-0.03643  0.04251  0.04009"/>
    <axis xyz="0  0  0"/>
    <limit effort="0" lower="0" upper="0" velocity="0"/>
  </joint>
  <joint name="Suport_Dyn2_Roda_learn1" type="revolute">
    <parent link="Suport_Dyn2"/>
    <child link="Roda_learn1"/>
    <origin rpy="-1.5707  0      0" xyz="-0.01219 -0.01512 -0.00839"/>
    <axis xyz="0.00000000e+00  -1.00000000e+00   9.00000000e-05"/>
    <limit effort="-1.0" lower="-1.79769e+308" upper="1.79769e+308" velocity="-1.0"/>
  </joint>
  <joint name="Chassi1_Suport_Dyn2" type="fixed">
    <parent link="Chassi1"/>
    <child link="Suport_Dyn2"/>
    <origin rpy="0  0  0" xyz="-0.03977 -0.04547 -0.0195"/>
    <axis xyz="0  0  0"/>
    <limit effort="0" lower="0" upper="0" velocity="0"/>
  </joint>
  <joint name="Chassi1_SuportDyn1" type="fixed">
    <parent link="Chassi1"/>
    <child link="SuportDyn1"/>
    <origin rpy="0  0  0" xyz="-0.03979  0.04602 -0.0216"/>
    <axis xyz="0  0  0"/>
    <limit effort="0" lower="0" upper="0" velocity="0"/>
  </joint>
  <joint name="Chassi1_Chassi3" type="fixed">
    <parent link="Chassi1"/>
    <child link="Chassi3"/>
    <origin rpy="0  0  0" xyz="0.04442 -0.00052 -0.0227"/>
    <axis xyz="0  0  0"/>
    <limit effort="0" lower="0" upper="0" velocity="0"/>
  </joint>
  <joint name="Chassi2_Chassi1" type="fixed">
    <parent link="Chassi2"/>
    <child link="Chassi1"/>
    <origin rpy="0  0  0" xyz="-0.0095  -0.00232 -0.0188"/>
    <axis xyz="0  0  0"/>
    <limit effort="0" lower="0" upper="0" velocity="0"/>
  </joint>
  <joint name="Chassi3_Segurabola" type="fixed">
    <parent link="Chassi3"/>
    <child link="Segurabola"/>
    <origin rpy="0  0  0" xyz="-0.00202 -0.00014 -0.0258"/>
    <axis xyz="0  0  0"/>
    <limit effort="0" lower="0" upper="0" velocity="0"/>
  </joint>
  <joint name="Empurrabola_Esfera" type="continuous">
    <parent link="Empurrabola"/>
    <child link="Esfera"/>
    <origin rpy="0  0  0" xyz="0    0   -0.01"/>
    <axis xyz="0  0  0"/>
    <limit effort="0" lower="0" upper="0" velocity="0"/>
  </joint>
  <joint name="Segurabola_Empurrabola" type="fixed">
    <parent link="Segurabola"/>
    <child link="Empurrabola"/>
    <origin rpy="0  0  0" xyz="-0.00353  0.03951 -0.0272"/>
    <axis xyz="0  0  0"/>
    <limit effort="0" lower="0" upper="0" velocity="0"/>
  </joint>
  <joint name="SuportDyn1_Roda_learn" type="revolute">
    <parent link="SuportDyn1"/>
    <child link="Roda_learn"/>
    <origin rpy="1.5707  0      0" xyz="-0.01218  0.01477 -0.00629"/>
    <axis xyz="0.00000000e+00   1.00000000e+00   9.00000000e-05"/>
    <limit effort="-1.0" lower="-1.79769e+308" upper="1.79769e+308" velocity="-1.0"/>
  </joint>
  <link name="Capa">
    <inertial>
      <mass value="0.078"/>
      <origin rpy="0  0  0" xyz="0  0  0"/>
      <inertia ixx="0.00011" ixy="1.2e-07" ixz="1.165e-05" iyy="0.0001956" iyz="0" izz="0.0002917"/>
    </inertial>
    <collision name="RobotC2_0_0__collision">
      <origin rpy="0  0  0" xyz="-0.06257  0.03853  0.06819"/>
      <geometry>
        <mesh filename="package://learnbotics/meshes/Capa.stl" scale="1 1 1"/>
      </geometry>
    </collision>
    <visual name="RobotC2_0_0__visual">
      <origin rpy="0  0  0" xyz="-0.06257  0.03853  0.06819"/>
      <geometry>
        <mesh filename="package://learnbotics/meshes/Capa.stl" scale="1 1 1"/>
      </geometry>
    </visual>
  </link>
  <link name="Suport_Dyn2">
    <inertial>
      <mass value="0.012"/>
      <origin rpy="0  0  0" xyz="0  0  0"/>
      <inertia ixx="1.79e-06" ixy="0" ixz="0" iyy="1e-05" iyz="0" izz="8.76e-06"/>
    </inertial>
    <collision name="RobotC2_0_0__collision">
      <origin rpy="0  0  0" xyz="0  0  0"/>
      <geometry>
        <mesh filename="package://learnbotics/meshes/Suport_Dyn2.stl" scale="1 1 1"/>
      </geometry>
    </collision>
    <visual name="RobotC2_0_0__visual">
      <origin rpy="0  0  0" xyz="0  0  0"/>
      <geometry>
        <mesh filename="package://learnbotics/meshes/Suport_Dyn2.stl" scale="1 1 1"/>
      </geometry>
    </visual>
  </link>
  <link name="Chassi1">
    <inertial>
      <mass value="0.102"/>
      <origin rpy="0  0  0" xyz="0  0  0"/>
      <inertia ixx="0.0001581" ixy="0" ixz="0" iyy="0.0002334" iyz="0" izz="0.0003755"/>
    </inertial>
    <collision name="RobotC2_0_0__collision">
      <origin rpy="0  0  0" xyz="0  0  0"/>
      <geometry>
        <mesh filename="package://learnbotics/meshes/Chassi1.stl" scale="1 1 1"/>
      </geometry>
    </collision>
    <visual name="RobotC2_0_0__visual">
      <origin rpy="0  0  0" xyz="0  0  0"/>
      <geometry>
        <mesh filename="package://learnbotics/meshes/Chassi1.stl" scale="1 1 1"/>
      </geometry>
    </visual>
  </link>
  <link name="Chassi2">
    <inertial>
      <mass value="0.07"/>
      <origin rpy="0  0  0" xyz="0  0  0"/>
      <inertia ixx="6.493e-05" ixy="0" ixz="9.92e-06" iyy="0.0002235" iyz="0" izz="0.0002834"/>
    </inertial>
    <collision name="RobotC2_0_0__collision">
      <origin rpy="0  0  0" xyz="0  0  0"/>
      <geometry>
        <mesh filename="package://learnbotics/meshes/Chassi2.stl" scale="1 1 1"/>
      </geometry>
    </collision>
    <visual name="RobotC2_0_0__visual">
      <origin rpy="0  0  0" xyz="0  0  0"/>
      <geometry>
        <mesh filename="package://learnbotics/meshes/Chassi2.stl" scale="1 1 1"/>
      </geometry>
    </visual>
  </link>
  <link name="Chassi3">
    <inertial>
      <mass value="0.036"/>
      <origin rpy="0  0  0" xyz="0  0  0"/>
      <inertia ixx="5.101e-05" ixy="0" ixz="0" iyy="1e-05" iyz="0" izz="5.812e-05"/>
    </inertial>
    <collision name="RobotC2_0_0__collision">
      <origin rpy="0  0  0" xyz="0  0  0"/>
      <geometry>
        <mesh filename="package://learnbotics/meshes/Chassi3.stl" scale="1 1 1"/>
      </geometry>
    </collision>
    <visual name="RobotC2_0_0__visual">
      <origin rpy="0  0  0" xyz="0  0  0"/>
      <geometry>
        <mesh filename="package://learnbotics/meshes/Chassi3.stl" scale="1 1 1"/>
      </geometry>
    </visual>
  </link>
  <link name="Empurrabola">
    <inertial>
      <mass value="0.006"/>
      <origin rpy="0  0  0" xyz="0  0  0"/>
      <inertia ixx="3.9e-07" ixy="0" ixz="0" iyy="3.9e-07" iyz="0" izz="4e-07"/>
    </inertial>
    <collision name="RobotC2_0_0__collision">
      <origin rpy="0  0  0" xyz="0  0  0"/>
      <geometry>
        <mesh filename="package://learnbotics/meshes/Empurrabola.stl" scale="1 1 1"/>
      </geometry>
    </collision>
    <visual name="RobotC2_0_0__visual">
      <origin rpy="0  0  0" xyz="0  0  0"/>
      <geometry>
        <mesh filename="package://learnbotics/meshes/Empurrabola.stl" scale="1 1 1"/>
      </geometry>
    </visual>
  </link>
  <link name="Esfera">
    <inertial>
      <mass value="0.004"/>
      <origin rpy="0  0  0" xyz="0  0  0"/>
      <inertia ixx="1.7e-07" ixy="0" ixz="0" iyy="1.7e-07" iyz="0" izz="1.7e-07"/>
    </inertial>
    <collision name="RobotC2_0_0__collision">
      <origin rpy="0  0  0" xyz="0  0  0"/>
      <geometry>
        <mesh filename="package://learnbotics/meshes/Esfera 15mm.stl" scale="1 1 1"/>
      </geometry>
    </collision>
    <visual name="RobotC2_0_0__visual">
      <origin rpy="0  0  0" xyz="0  0  0"/>
      <geometry>
        <mesh filename="package://learnbotics/meshes/Esfera 15mm.stl" scale="1 1 1"/>
      </geometry>
    </visual>
  </link>
  <link name="Roda_learn1">
    <inertial>
      <mass value="0.027"/>
      <origin rpy="0  0  0" xyz="0  0  0"/>
      <inertia ixx="1.095e-05" ixy="0" ixz="0" iyy="2.138e-05" iyz="0" izz="1.095e-05"/>
    </inertial>
    <collision name="RobotC2_0_0__collision">
      <origin rpy="1.5707  0      0" xyz="0  0  0"/>
      <geometry>
        <mesh filename="package://learnbotics/meshes/Roda_learn.stl" scale="1 1 1"/>
      </geometry>
    </collision>
    <visual name="RobotC2_0_0__visual">
      <origin rpy="1.5707  0      0" xyz="0  0  0"/>
      <geometry>
        <mesh filename="package://learnbotics/meshes/Roda_learn.stl" scale="1 1 1"/>
      </geometry>
    </visual>
  </link>
  <link name="Roda_learn">
    <inertial>
      <mass value="0.027"/>
      <origin rpy="0  0  0" xyz="0  0  0"/>
      <inertia ixx="1.095e-05" ixy="0" ixz="0" iyy="2.138e-05" iyz="0" izz="1.095e-05"/>
    </inertial>
    <collision name="RobotC2_0_0__collision">
      <origin rpy="1.5707  0      0" xyz="0  0  0"/>
      <geometry>
        <mesh filename="package://learnbotics/meshes/Roda_learn.stl" scale="1 1 1"/>
      </geometry>
    </collision>
    <visual name="RobotC2_0_0__visual">
      <origin rpy="1.5707  0      0" xyz="0  0  0"/>
      <geometry>
        <mesh filename="package://learnbotics/meshes/Roda_learn.stl" scale="1 1 1"/>
      </geometry>
    </visual>
  </link>
  <link name="Segurabola">
    <inertial>
      <mass value="0.012"/>
      <origin rpy="0  0  0" xyz="0  0  0"/>
      <inertia ixx="2.33e-06" ixy="0" ixz="0" iyy="2.52e-06" iyz="0" izz="3.15e-06"/>
    </inertial>
    <collision name="RobotC2_0_0__collision">
      <origin rpy="0  0  0" xyz="-0.00303  0.04001 -0.01806"/>
      <geometry>
        <mesh filename="package://learnbotics/meshes/Segurabola.stl" scale="1 1 1"/>
      </geometry>
    </collision>
    <visual name="RobotC2_0_0__visual">
      <origin rpy="0  0  0" xyz="-0.00303  0.04001 -0.01806"/>
      <geometry>
        <mesh filename="package://learnbotics/meshes/Segurabola.stl" scale="1 1 1"/>
      </geometry>
    </visual>
  </link>
  <link name="SuportDyn1">
    <inertial>
      <mass value="0.012"/>
      <origin rpy="0  0  0" xyz="0  0  0"/>
      <inertia ixx="1.79e-06" ixy="0" ixz="0" iyy="1e-05" iyz="0" izz="8.76e-06"/>
    </inertial>
    <collision name="RobotC2_0_0__collision">
      <origin rpy="0  0  0" xyz="0  0  0"/>
      <geometry>
        <mesh filename="package://learnbotics/meshes/SuportDyn1.stl" scale="1 1 1"/>
      </geometry>
    </collision>
    <visual name="RobotC2_0_0__visual">
      <origin rpy="0  0  0" xyz="0  0  0"/>
      <geometry>
        <mesh filename="package://learnbotics/meshes/SuportDyn1.stl" scale="1 1 1"/>
      </geometry>
    </visual>
  </link>
</robot>
